Workbook
Name Entertainment: 'Scenario Manager'!$B$5
Name Food: 'Scenario Manager'!$B$8
Name Housing: 'Scenario Manager'!$B$4
Name Income: 'Scenario Manager'!$B$12
Name Loans: 'Scenario Manager'!$B$7
Name Personal_Care: 'Scenario Manager'!$B$9
Name Savings: 'Scenario Manager'!$B$13
Name Slicer_City: #N/A
Name Slicer_Dept: #N/A
Name Slicer_Gender: #N/A
Name Slicer_Grade: #N/A
Name Total_Cost: 'Scenario Manager'!$B$10
Name Transportation: 'Scenario Manager'!$B$6

Sheet Dataset
A1: Student_ID | B1: Name | C1: Last Name | D1: Dept | E1: Mark | F1: Attendance (%) | G1: Gender_Age
A2: S1000 | B2: Ravi | C2: Kumar | D2: Arts | E2: 76 | F2: 82 | G2: M22
A3: S1001 | B3: Mohan | C3: Raj | D3: arts | E3: 71 | G3: M34
A4: S1002 | B4: deepthiKha | C4: Rani | D4: Arts | E4: 39 | F4: 65 | G4: F21
A5: S1003 | B5: Manohar | C5: Babu | D5: Commerce | E5: 72 | F5: 93 | G5: M25
A6: S1004 | B6: Priyanka | C6: Devi | D6: Science | E6: 60 | F6: 73 | G6: F23
A7: S1005 | B7: Vinoth | C7: Muthu | D7: Commerce | E7: 84 | F7: 62 | G7: M26
A8: S1006 | B8: Shanthi | C8: Lakshmi | D8: Arts | E8: 60 | F8: 86 | G8: F29
A9: S1007 | B9: manimegalai | C9: Selvi | D9: Commerce | E9: 98 | F9: 96 | G9: F28
A10: S1008 | B10: Karthi | C10: Velu | D10: Commerce | E10: 44 | F10: 95 | G10: M22
A11: S1009 | B11: Mari | C11: Gopi | D11: Science | E11: 94 | F11: 66 | G11: M23
A12: S1010 | B12: Mahesh | C12: Sekar | D12: arts | F12: 65 | G12: M24
A13: S1011 | B13: sangeetha | C13: Raji | D13: Science | E13: 51 | F13: 61 | G13: F22
A14: S1012 | B14: Raghul | C14: Arul | D14: Arts | E14: 73 | F14: 91 | G14: M25
A15: S1013 | B15: Jothi | C15: Radha | D15: Commerce | E15: 60 | G15: F26
A16: S1014 | B16: Anisha | C16: Meena | D16: Commerce | E16: 41 | F16: 88 | G16: F27
A17: S1015 | B17: Venkat | C17: Hari | D17: Commerce | E17: 35 | F17: 90 | G17: M22
A18: S1016 | B18: Chandru | C18: Raja | D18: Science | E18: 55 | F18: 96 | G18: M24
A19: S1017 | B19: Dinesh | C19: Kumar | D19: Arts | E19: 74 | F19: 71 | G19: M23
A20: S1018 | B20: Poorvika | C20: Devi | D20: Science | F20: 62 | G20: F21
A21: S1019 | B21: Vimal | C21: Arasu | D21: Commerce | E21: 53 | F21: 100 | G21: M25
A22: S1016 | B22: Chandru | C22: Raja | D22: Science | E22: 55 | F22: 96 | G22: M24
A23: S1020 | B23: Parthiban | C23: Bala | D23: Science | E23: 80 | F23: 67 | G23: M26
A24: S1021 | B24: Santhosh | C24: Gokul | D24: Arts | E24: 62 | F24: 83 | G24: M23
A25: S1022 | B25: Keerthika | C25: divya | D25: Arts | E25: 98 | F25: 92 | G25: F24
A26: S1023 | B26: Reeta | C26: Yamuna | D26: Arts | E26: 41 | F26: 62 | G26: F28
A27: S1024 | B27: Lalitha | C27: Nila | D27: Science | E27: 37 | F27: 73 | G27: F25
A28: S1025 | B28: Sridhar | C28: Ramu | D28: Commerce | E28: 76 | F28: 80 | G28: M27
A29: S1016 | B29: Chandru | C29: Raja | D29: Science | E29: 55 | F29: 96 | G29: M24
A30: S1026 | B30: Kavitha | C30: Banu | D30: Commerce | E30: 71 | F30: 84 | G30: F26
A31: S1027 | B31: Murugesan | C31: Kani | D31: Commerce | F31: 65 | G31: M23
A32: S1028 | B32: Gandhi | C32: Selvam | D32: Arts | E32: 54 | F32: 99 | G32: M28
A33: S1029 | B33: Sridhar | C33: Ramu | D33: Commerce | E33: 76 | F33: 80 | G33: M27
A34: S1030 | B34: Varshini | C34: Devi | D34: Science | E34: 90 | F34: 66 | G34: F22
A35: S1031 | B35: Indhumathi | C35: Nithya | D35: Arts | E35: 80 | F35: 91 | G35: F29
A36: S1032 | B36: Janani | C36: Uma | D36: Science | E36: 57 | F36: 72 | G36: F23
A37: S1033 | B37: Bharath | C37: Guru | D37: Science | E37: 92 | F37: 87 | G37: M25
A38: S1034 | B38: Akash | C38: Vignesh | D38: Arts | E38: 52 | F38: 84 | G38: M22
A39: S1035 | B39: Murugesan | C39: kani | D39: Commerce | E39: 53 | F39: 65 | G39: M23
A40: S1036 | B40: Nirmal | C40: Prakash | D40: Commerce | E40: 97 | F40: 88 | G40: M24

Sheet Dataset_Cleaning
A1: Student_ID | B1: Name | C1: Last Name | D1: Dept | E1: Mark | F1: Attendance (%) | G1: Gender | H1: Age | I1: Full_Name | J1: Marks | K1: Attendance in %
A2: S1000 | B2: Ravi | C2: Kumar | D2: Arts | E2: 76 | F2: 82 | G2: M | H2: 22 | I2: =PROPER(CONCATENATE(B2, " ", C2)) -> Ravi Kumar | J2: =IF(E2="", AVERAGEIF(Table13[Dept], D2, Table13[Mark]), E2) -> 76 | K2: =IF(F2="", ROUND(AVERAGE(Table13[Attendance (%)]),0), F2) -> 82
A3: S1001 | B3: Mohan | C3: Raj | D3: Arts | E3: 71 | G3: M | H3: 34 | I3: =PROPER(CONCATENATE(B3, " ", C3)) -> Mohan Raj | J3: =IF(E3="", AVERAGEIF(Table13[Dept], D3, Table13[Mark]), E3) -> 71 | K3: =IF(F3="", ROUND(AVERAGE(Table13[Attendance (%)]),0), F3) -> 80
A4: S1002 | B4: deepthiKha | C4: Rani | D4: Arts | E4: 39 | F4: 65 | G4: F | H4: 21 | I4: =PROPER(CONCATENATE(B4, " ", C4)) -> Deepthikha Rani | J4: =IF(E4="", AVERAGEIF(Table13[Dept], D4, Table13[Mark]), E4) -> 39 | K4: =IF(F4="", ROUND(AVERAGE(Table13[Attendance (%)]),0), F4) -> 65
A5: S1003 | B5: Manohar | C5: Babu | D5: Commerce | E5: 72 | F5: 93 | G5: M | H5: 25 | I5: =PROPER(CONCATENATE(B5, " ", C5)) -> Manohar Babu | J5: =IF(E5="", AVERAGEIF(Table13[Dept], D5, Table13[Mark]), E5) -> 72 | K5: =IF(F5="", ROUND(AVERAGE(Table13[Attendance (%)]),0), F5) -> 93
A6: S1004 | B6: Priyanka | C6: Devi | D6: Science | E6: 60 | F6: 73 | G6: F | H6: 23 | I6: =PROPER(CONCATENATE(B6, " ", C6)) -> Priyanka Devi | J6: =IF(E6="", AVERAGEIF(Table13[Dept], D6, Table13[Mark]), E6) -> 60 | K6: =IF(F6="", ROUND(AVERAGE(Table13[Attendance (%)]),0), F6) -> 73
A7: S1005 | B7: Vinoth | C7: Muthu | D7: Commerce | E7: 84 | F7: 62 | G7: M | H7: 26 | I7: =PROPER(CONCATENATE(B7, " ", C7)) -> Vinoth Muthu | J7: =IF(E7="", AVERAGEIF(Table13[Dept], D7, Table13[Mark]), E7) -> 84 | K7: =IF(F7="", ROUND(AVERAGE(Table13[Attendance (%)]),0), F7) -> 62
A8: S1006 | B8: Shanthi | C8: Lakshmi | D8: Arts | E8: 60 | F8: 86 | G8: F | H8: 29 | I8: =PROPER(CONCATENATE(B8, " ", C8)) -> Shanthi Lakshmi | J8: =IF(E8="", AVERAGEIF(Table13[Dept], D8, Table13[Mark]), E8) -> 60 | K8: =IF(F8="", ROUND(AVERAGE(Table13[Attendance (%)]),0), F8) -> 86
A9: S1007 | B9: manimegalai | C9: Selvi | D9: Commerce | E9: 98 | F9: 96 | G9: F | H9: 28 | I9: =PROPER(CONCATENATE(B9, " ", C9)) -> Manimegalai Selvi | J9: =IF(E9="", AVERAGEIF(Table13[Dept], D9, Table13[Mark]), E9) -> 98 | K9: =IF(F9="", ROUND(AVERAGE(Table13[Attendance (%)]),0), F9) -> 96
A10: S1008 | B10: Karthi | C10: Velu | D10: Commerce | E10: 44 | F10: 95 | G10: M | H10: 22 | I10: =PROPER(CONCATENATE(B10, " ", C10)) -> Karthi Velu | J10: =IF(E10="", AVERAGEIF(Table13[Dept], D10, Table13[Mark]), E10) -> 44 | K10: =IF(F10="", ROUND(AVERAGE(Table13[Attendance (%)]),0), F10) -> 95
A11: S1009 | B11: Mari | C11: Gopi | D11: Science | E11: 94 | F11: 66 | G11: M | H11: 23 | I11: =PROPER(CONCATENATE(B11, " ", C11)) -> Mari Gopi | J11: =IF(E11="", AVERAGEIF(Table13[Dept], D11, Table13[Mark]), E11) -> 94 | K11: =IF(F11="", ROUND(AVERAGE(Table13[Attendance (%)]),0), F11) -> 66
A12: S1010 | B12: Mahesh | C12: Sekar | D12: Arts | F12: 65 | G12: M | H12: 24 | I12: =PROPER(CONCATENATE(B12, " ", C12)) -> Mahesh Sekar | J12: =IF(E12="", AVERAGEIF(Table13[Dept], D12, Table13[Mark]), E12) -> 65 | K12: =IF(F12="", ROUND(AVERAGE(Table13[Attendance (%)]),0), F12) -> 65
A13: S1011 | B13: sangeetha | C13: Raji | D13: Science | E13: 51 | F13: 61 | G13: F | H13: 22 | I13: =PROPER(CONCATENATE(B13, " ", C13)) -> Sangeetha Raji | J13: =IF(E13="", AVERAGEIF(Table13[Dept], D13, Table13[Mark]), E13) -> 51 | K13: =IF(F13="", ROUND(AVERAGE(Table13[Attendance (%)]),0), F13) -> 61
A14: S1012 | B14: Raghul | C14: Arul | D14: Arts | E14: 73 | F14: 91 | G14: M | H14: 25 | I14: =PROPER(CONCATENATE(B14, " ", C14)) -> Raghul Arul | J14: =IF(E14="", AVERAGEIF(Table13[Dept], D14, Table13[Mark]), E14) -> 73 | K14: =IF(F14="", ROUND(AVERAGE(Table13[Attendance (%)]),0), F14) -> 91
A15: S1013 | B15: Jothi | C15: Radha | D15: Commerce | E15: 60 | G15: F | H15: 26 | I15: =PROPER(CONCATENATE(B15, " ", C15)) -> Jothi Radha | J15: =IF(E15="", AVERAGEIF(Table13[Dept], D15, Table13[Mark]), E15) -> 60 | K15: =IF(F15="", ROUND(AVERAGE(Table13[Attendance (%)]),0), F15) -> 80
A16: S1014 | B16: Anisha | C16: Meena | D16: Commerce | E16: 41 | F16: 88 | G16: F | H16: 27 | I16: =PROPER(CONCATENATE(B16, " ", C16)) -> Anisha Meena | J16: =IF(E16="", AVERAGEIF(Table13[Dept], D16, Table13[Mark]), E16) -> 41 | K16: =IF(F16="", ROUND(AVERAGE(Table13[Attendance (%)]),0), F16) -> 88
A17: S1015 | B17: Venkat | C17: Hari | D17: Commerce | E17: 35 | F17: 90 | G17: M | H17: 22 | I17: =PROPER(CONCATENATE(B17, " ", C17)) -> Venkat Hari | J17: =IF(E17="", AVERAGEIF(Table13[Dept], D17, Table13[Mark]), E17) -> 35 | K17: =IF(F17="", ROUND(AVERAGE(Table13[Attendance (%)]),0), F17) -> 90
A18: S1016 | B18: Chandru | C18: Raja | D18: Science | E18: 55 | F18: 96 | G18: M | H18: 24 | I18: =PROPER(CONCATENATE(B18, " ", C18)) -> Chandru Raja | J18: =IF(E18="", AVERAGEIF(Table13[Dept], D18, Table13[Mark]), E18) -> 55 | K18: =IF(F18="", ROUND(AVERAGE(Table13[Attendance (%)]),0), F18) -> 96
A19: S1017 | B19: Dinesh | C19: Kumar | D19: Arts | E19: 74 | F19: 71 | G19: M | H19: 23 | I19: =PROPER(CONCATENATE(B19, " ", C19)) -> Dinesh Kumar | J19: =IF(E19="", AVERAGEIF(Table13[Dept], D19, Table13[Mark]), E19) -> 74 | K19: =IF(F19="", ROUND(AVERAGE(Table13[Attendance (%)]),0), F19) -> 71
A20: S1018 | B20: Poorvika | C20: Devi | D20: Science | F20: 62 | G20: F | H20: 21 | I20: =PROPER(CONCATENATE(B20, " ", C20)) -> Poorvika Devi | J20: =IF(E20="", AVERAGEIF(Table13[Dept], D20, Table13[Mark]), E20) -> 66 | K20: =IF(F20="", ROUND(AVERAGE(Table13[Attendance (%)]),0), F20) -> 62
A21: S1019 | B21: Vimal | C21: Arasu | D21: Commerce | E21: 53 | F21: 100 | G21: M | H21: 25 | I21: =PROPER(CONCATENATE(B21, " ", C21)) -> Vimal Arasu | J21: =IF(E21="", AVERAGEIF(Table13[Dept], D21, Table13[Mark]), E21) -> 53 | K21: =IF(F21="", ROUND(AVERAGE(Table13[Attendance (%)]),0), F21) -> 100
A22: S1016 | B22: Chandru | C22: Raja | D22: Science | E22: 55 | F22: 96 | G22: M | H22: 24 | I22: =PROPER(CONCATENATE(B22, " ", C22)) -> Chandru Raja | J22: =IF(E22="", AVERAGEIF(Table13[Dept], D22, Table13[Mark]), E22) -> 55 | K22: =IF(F22="", ROUND(AVERAGE(Table13[Attendance (%)]),0), F22) -> 96
A23: S1020 | B23: Parthiban | C23: Bala | D23: Science | E23: 80 | F23: 67 | G23: M | H23: 26 | I23: =PROPER(CONCATENATE(B23, " ", C23)) -> Parthiban Bala | J23: =IF(E23="", AVERAGEIF(Table13[Dept], D23, Table13[Mark]), E23) -> 80 | K23: =IF(F23="", ROUND(AVERAGE(Table13[Attendance (%)]),0), F23) -> 67
A24: S1021 | B24: Santhosh | C24: Gokul | D24: Arts | E24: 62 | F24: 83 | G24: M | H24: 23 | I24: =PROPER(CONCATENATE(B24, " ", C24)) -> Santhosh Gokul | J24: =IF(E24="", AVERAGEIF(Table13[Dept], D24, Table13[Mark]), E24) -> 62 | K24: =IF(F24="", ROUND(AVERAGE(Table13[Attendance (%)]),0), F24) -> 83
A25: S1022 | B25: Keerthika | C25: divya | D25: Arts | E25: 98 | F25: 92 | G25: F | H25: 24 | I25: =PROPER(CONCATENATE(B25, " ", C25)) -> Keerthika Divya | J25: =IF(E25="", AVERAGEIF(Table13[Dept], D25, Table13[Mark]), E25) -> 98 | K25: =IF(F25="", ROUND(AVERAGE(Table13[Attendance (%)]),0), F25) -> 92
A26: S1023 | B26: Reeta | C26: Yamuna | D26: Arts | E26: 41 | F26: 62 | G26: F | H26: 28 | I26: =PROPER(CONCATENATE(B26, " ", C26)) -> Reeta Yamuna | J26: =IF(E26="", AVERAGEIF(Table13[Dept], D26, Table13[Mark]), E26) -> 41 | K26: =IF(F26="", ROUND(AVERAGE(Table13[Attendance (%)]),0), F26) -> 62
A27: S1024 | B27: Lalitha | C27: Nila | D27: Science | E27: 37 | F27: 73 | G27: F | H27: 25 | I27: =PROPER(CONCATENATE(B27, " ", C27)) -> Lalitha Nila | J27: =IF(E27="", AVERAGEIF(Table13[Dept], D27, Table13[Mark]), E27) -> 37 | K27: =IF(F27="", ROUND(AVERAGE(Table13[Attendance (%)]),0), F27) -> 73
A28: S1025 | B28: Sridhar | C28: Ramu | D28: Commerce | E28: 76 | F28: 80 | G28: M | H28: 27 | I28: =PROPER(CONCATENATE(B28, " ", C28)) -> Sridhar Ramu | J28: =IF(E28="", AVERAGEIF(Table13[Dept], D28, Table13[Mark]), E28) -> 76 | K28: =IF(F28="", ROUND(AVERAGE(Table13[Attendance (%)]),0), F28) -> 80
A29: S1016 | B29: Chandru | C29: Raja | D29: Science | E29: 55 | F29: 96 | G29: M | H29: 24 | I29: =PROPER(CONCATENATE(B29, " ", C29)) -> Chandru Raja | J29: =IF(E29="", AVERAGEIF(Table13[Dept], D29, Table13[Mark]), E29) -> 55 | K29: =IF(F29="", ROUND(AVERAGE(Table13[Attendance (%)]),0), F29) -> 96
A30: S1026 | B30: Kavitha | C30: Banu | D30: Commerce | E30: 99 | F30: 84 | G30: F | H30: 26 | I30: =PROPER(CONCATENATE(B30, " ", C30)) -> Kavitha Banu | J30: =IF(E30="", AVERAGEIF(Table13[Dept], D30, Table13[Mark]), E30) -> 99 | K30: =IF(F30="", ROUND(AVERAGE(Table13[Attendance (%)]),0), F30) -> 84
A31: S1027 | B31: Murugesan | C31: Kani | D31: Commerce | F31: 65 | G31: M | H31: 23 | I31: =PROPER(CONCATENATE(B31, " ", C31)) -> Murugesan Kani | J31: =IF(E31="", AVERAGEIF(Table13[Dept], D31, Table13[Mark]), E31) -> 68.307692 | K31: =IF(F31="", ROUND(AVERAGE(Table13[Attendance (%)]),0), F31) -> 65
A32: S1028 | B32: Gandhi | C32: Selvam | D32: Arts | E32: 54 | F32: 99 | G32: M | H32: 28 | I32: =PROPER(CONCATENATE(B32, " ", C32)) -> Gandhi Selvam | J32: =IF(E32="", AVERAGEIF(Table13[Dept], D32, Table13[Mark]), E32) -> 54 | K32: =IF(F32="", ROUND(AVERAGE(Table13[Attendance (%)]),0), F32) -> 99
A33: S1029 | B33: Sridhar | C33: Ramu | D33: Commerce | E33: 76 | F33: 80 | G33: M | H33: 27 | I33: =PROPER(CONCATENATE(B33, " ", C33)) -> Sridhar Ramu | J33: =IF(E33="", AVERAGEIF(Table13[Dept], D33, Table13[Mark]), E33) -> 76 | K33: =IF(F33="", ROUND(AVERAGE(Table13[Attendance (%)]),0), F33) -> 80
A34: S1030 | B34: Varshini | C34: Devi | D34: Science | E34: 90 | F34: 66 | G34: F | H34: 22 | I34: =PROPER(CONCATENATE(B34, " ", C34)) -> Varshini Devi | J34: =IF(E34="", AVERAGEIF(Table13[Dept], D34, Table13[Mark]), E34) -> 90 | K34: =IF(F34="", ROUND(AVERAGE(Table13[Attendance (%)]),0), F34) -> 66
A35: S1031 | B35: Indhumathi | C35: Nithya | D35: Arts | E35: 80 | F35: 91 | G35: F | H35: 29 | I35: =PROPER(CONCATENATE(B35, " ", C35)) -> Indhumathi Nithya | J35: =IF(E35="", AVERAGEIF(Table13[Dept], D35, Table13[Mark]), E35) -> 80 | K35: =IF(F35="", ROUND(AVERAGE(Table13[Attendance (%)]),0), F35) -> 91
A36: S1032 | B36: Janani | C36: Uma | D36: Science | E36: 57 | F36: 72 | G36: F | H36: 23 | I36: =PROPER(CONCATENATE(B36, " ", C36)) -> Janani Uma | J36: =IF(E36="", AVERAGEIF(Table13[Dept], D36, Table13[Mark]), E36) -> 57 | K36: =IF(F36="", ROUND(AVERAGE(Table13[Attendance (%)]),0), F36) -> 72
A37: S1033 | B37: Bharath | C37: Guru | D37: Science | E37: 92 | F37: 87 | G37: M | H37: 25 | I37: =PROPER(CONCATENATE(B37, " ", C37)) -> Bharath Guru | J37: =IF(E37="", AVERAGEIF(Table13[Dept], D37, Table13[Mark]), E37) -> 92 | K37: =IF(F37="", ROUND(AVERAGE(Table13[Attendance (%)]),0), F37) -> 87
A38: S1034 | B38: Akash | C38: Vignesh | D38: Arts | E38: 52 | F38: 84 | G38: M | H38: 22 | I38: =PROPER(CONCATENATE(B38, " ", C38)) -> Akash Vignesh | J38: =IF(E38="", AVERAGEIF(Table13[Dept], D38, Table13[Mark]), E38) -> 52 | K38: =IF(F38="", ROUND(AVERAGE(Table13[Attendance (%)]),0), F38) -> 84
A39: S1035 | B39: Murugesan | C39: kani | D39: Commerce | E39: 53 | F39: 65 | G39: M | H39: 23 | I39: =PROPER(CONCATENATE(B39, " ", C39)) -> Murugesan Kani | J39: =IF(E39="", AVERAGEIF(Table13[Dept], D39, Table13[Mark]), E39) -> 53 | K39: =IF(F39="", ROUND(AVERAGE(Table13[Attendance (%)]),0), F39) -> 65
A40: S1036 | B40: Nirmal | C40: Prakash | D40: Commerce | E40: 97 | F40: 88 | G40: M | H40: 24 | I40: =PROPER(CONCATENATE(B40, " ", C40)) -> Nirmal Prakash | J40: =IF(E40="", AVERAGEIF(Table13[Dept], D40, Table13[Mark]), E40) -> 97 | K40: =IF(F40="", ROUND(AVERAGE(Table13[Attendance (%)]),0), F40) -> 88

Sheet cleaned
A1: Student_ID | B1: Full_Name | C1: Gender | D1: Dept | E1: Age | F1: Attendance in % | G1: Marks
A2: S1000 | B2: Ravi Kumar | C2: M | D2: Arts | E2: 22 | F2: 76 | G2: 82
A3: S1001 | B3: Mohan Raj | C3: M | D3: Arts | E3: 34 | F3: 71 | G3: 80
A4: S1002 | B4: Deepthikha Rani | C4: F | D4: Arts | E4: 21 | F4: 39 | G4: 65
A5: S1003 | B5: Manohar Babu | C5: M | D5: Commerce | E5: 25 | F5: 72 | G5: 93
A6: S1004 | B6: Priyanka Devi | C6: F | D6: Science | E6: 23 | F6: 60 | G6: 73
A7: S1005 | B7: Vinoth Muthu | C7: M | D7: Commerce | E7: 26 | F7: 84 | G7: 62
A8: S1006 | B8: Shanthi Lakshmi | C8: F | D8: Arts | E8: 29 | F8: 60 | G8: 86
A9: S1007 | B9: Manimegalai Selvi | C9: F | D9: Commerce | E9: 28 | F9: 98 | G9: 96
A10: S1008 | B10: Karthi Velu | C10: M | D10: Commerce | E10: 22 | F10: 44 | G10: 95
A11: S1009 | B11: Mari Gopi | C11: M | D11: Science | E11: 23 | F11: 94 | G11: 66
A12: S1010 | B12: Mahesh Sekar | C12: M | D12: Arts | E12: 24 | F12: 65 | G12: 65
A13: S1011 | B13: Sangeetha Raji | C13: F | D13: Science | E13: 22 | F13: 51 | G13: 61
... A40: S1036 | B40: Nirmal Prakash | C40: M | D40: Commerce | E40: 24 | F40: 97 | G40: 88

Sheet PIVOT
A3: Row Labels | B3: Average of Mark
A4: Arts | B4: 65.416667
A5: Commerce | B5: 65.6
A6: Science | B6: 63.5
A7: Grand Total | B7: 64.897436
A10: Row Labels | B10: Count of Student_ID
A11: Chennai | B11: 7
A12: Coimbatore | B12: 6
A13: Pudhukottai | B13: 4
A14: Salem | B14: 6
A15: Tenkasi | B15: 6
A16: Trichy | B16: 5
A17: Vellore | B17: 5
A18: Grand Total | B18: 39
A21: Row Labels | B21: Count of Student_ID
A22: A | B22: 7
A23: B | B23: 12
A24: C | B24: 16
A25: U | B25: 4
A26: Grand Total | B26: 39
A29: Average of Mark | B29: Column Labels
A30: Row Labels | B30: F | C30: M | D30: Grand Total
A31: Arts | B31: 63.6 | C31: 66.714286 | D31: 65.416667
A32: Commerce | B32: 67.5 | C32: 64.909091 | D32: 65.6
A33: Science | B33: 55.166667 | C33: 71.833333 | D33: 63.5
A34: Grand Total | B34: 61.266667 | C34: 67.166667 | D34: 64.897436
A39: Row Labels | B39: Max of Mark
A40: Arts | B40: 98
A41: Commerce | B41: 98
A42: Science | B42: 94
A43: Grand Total | B43: 98
A46: Row Labels | B46: Count of Student_ID
A47: A | B47: 7
A48: B | B48: 12
A49: C | B49: 16
A50: U | B50: 4
A51: Grand Total | B51: 39
A55: Row Labels | B55: Sum of Eligibilty
A56: 61 | B56: #VALUE!
A57: 62 | B57: #VALUE!
...

Sheet DASHBOARD
A1: STUDENT DASHBOARD

Sheet Scenario Summary
B2: Scenario Summary
D3: Current Values: | E3: s1 | F3: s2
E4: Created by Kumaran M on 03-10-2025 | F4: Created by Kumaran M on 03-10-2025
B5: Changing Cells:
C6: Housing | D6: 4000 | E6: 4000 | F6: 4000
C7: Entertainment | D7: 5000 | E7: 2000 | F7: 5000
C8: Transportation | D8: 2000 | E8: 1000 | F8: 2000
C9: Loans | D9: 2500 | E9: 2500 | F9: 2500
C10: Food | D10: 6000 | E10: 5000 | F10: 6000
C11: Personal_Care | D11: 1000 | E11: 500 | F11: 1000
C12: Income | D12: 22000 | E12: 20000 | F12: 22000
B13: Result Cells:
C14: Savings | D14: 1500 | E14: 5000 | F14: 1500
B15: Notes: Current Values column represents values of changing cells at
B16: time Scenario Summary Report was created. Changing cells for each
B17: scenario are highlighted in gray.

Sheet Scenario Manager
A1: Personal Monthly Budget Table
A3: Category | B3: Cost
A4: Housing | B4: 4000
A5: Entertainment | B5: 5000
A6: Transportation | B6: 2000
A7: Loans | B7: 2500
A8: Food | B8: 6000
A9: Personal Care | B9: 1000
A10: Total Cost | B10: =SUM(B4:B9) -> 20500
A12: Income | B12: 22000
A13: Savings | B13: =B12 - B10 -> 1500

Sheet VLKP
A1: Student_ID | B1: Name | C1: Last Name | D1: Dept | E1: Mark | F1: Attendance (%) | G1: Gender | H1: Age
A2: S1000 | B2: Ravi | C2: Kumar | D2: Arts | E2: 76 | F2: 82 | G2: M | H2: 22 | J2: What is the Dept of
A3: S1001 | B3: Mohan | C3: Raj | D3: Commerce | E3: 71 | F3: 91 | G3: M | H3: 34
A4: S1002 | B4: Deepika | C4: Rani | D4: Arts | E4: 39 | F4: 65 | G4: F | H4: 21 | J4: Mohan | K4: =VLOOKUP(J4, $B$2:$H$40, 3, 0) -> Commerce
A5: S1003 | B5: Manohar | C5: Babu | D5: Commerce | E5: 72 | F5: 93 | G5: M | H5: 25 | J5: Ravi | K5: =VLOOKUP(J5, $B$2:$H$40, 3, 0) -> Arts
A6: S1004 | B6: Priyanka | C6: Devi | D6: Science | E6: 60 | F6: 73 | G6: F | H6: 23 | J6: Anisha | K6: =VLOOKUP(J6, $B$2:$H$40, 3, 0) -> Commerce
A7: S1005 | B7: Vinoth | C7: Muthu | D7: Commerce | E7: 84 | F7: 62 | G7: M | H7: 26 | J7: poorvika | K7: =VLOOKUP(J7, $B$2:$H$40, 3, 0) -> Science
A8: S1006 | B8: Shanthi | C8: Lakshmi | D8: Arts | E8: 60 | F8: 86 | G8: F | H8: 29
A9: S1007 | B9: Manimegalai | C9: Selvi | D9: Commerce | E9: 98 | F9: 96 | G9: F | H9: 28 | J9: Priyanka | K9: =INDEX(H2:H11, 5) -> 23
A10: S1008 | B10: Karthi | C10: Velu | D10: Commerce | E10: 44 | F10: 95 | G10: M | H10: 22
A11: S1009 | B11: Mari | C11: Gopi | D11: Science | E11: 94 | F11: 66 | G11: M | H11: 23
A12: S1010 | B12: Mahesh | C12: Sekar | D12: Arts | E12: 78 | F12: 65 | G12: M | H12: 24 | J12: Bharath
A13: S1011 | B13: Sangeetha | C13: Raji | D13: Science | E13: 51 | F13: 61 | G13: F | H13: 22 | J13: Kavitha | K13: =INDEX(C2:C40, MATCH(J13, B2:B40,0)) -> Banu
A14: S1012 | B14: Raghul | C14: Arul | D14: Arts | E14: 73 | F14: 91 | G14: M | H14: 25
A15: S1013 | B15: Jothi | C15: Radha | D15: Commerce | E15: 60 | F15: 88 | G15: F | H15: 26 | J15: =INDEX($H$2:$H$40, MATCH(J12,$B$2:$B$40,0)) -> 25
A16: S1014 | B16: Anisha | C16: Meena | D16: Commerce | E16: 41 | F16: 88 | G16: F | H16: 27
A17: S1015 | B17: Venkat | C17: Hari | D17: Commerce | E17: 35 | F17: 90 | G17: M | H17: 22
A18: S1016 | B18: Chandru | C18: Raja | D18: Science | E18: 55 | F18: 96 | G18: M | H18: 24
A19: S1017 | B19: Dinesh | C19: Kumar | D19: Arts | E19: 74 | F19: 71 | G19: M | H19: 23
A20: S1018 | B20: Poorvika | C20: Devi | D20: Science | E20: 36 | F20: 62 | G20: F | H20: 21
A21: S1019 | B21: Vimal | C21: Arasu | D21: Commerce | E21: 53 | F21: 100 | G21: M | H21: 25
A22: S1016 | B22: Chandru | C22: Raja | D22: Science | E22: 55 | F22: 96 | G22: M | H22: 24
A23: S1020 | B23: Parthiban | C23: Bala | D23: Science | E23: 80 | F23: 67 | G23: M | H23: 26
A24: S1021 | B24: Santhosh | C24: Gokul | D24: Arts | E24: 62 | F24: 83 | G24: M | H24: 23
A25: S1022 | B25: Keerthika | C25: Divya | D25: Arts | E25: 98 | F25: 92 | G25: F | H25: 24
A26: S1023 | B26: Reeta | C26: Yamuna | D26: Arts | E26: 41 | F26: 62 | G26: F | H26: 28
A27: S1024 | B27: Lalitha | C27: Nila | D27: Science | E27: 37 | F27: 73 | G27: F | H27: 25
... A40: S1036 | B40: Nirmal | C40: Prakash | D40: Commerce | E40: 97 | F40: 88 | G40: M | H40: 24

Sheet VLKP (2)
A1: Name | B1: Lname | C1: Dept | D1: Mark | E1: Attendance | F1: Gender | G1: Age
A2: Ravi | B2: =VLOOKUP($A2,VLKP!$B$2:$H$40, 2, 0) -> Kumar | C2: =VLOOKUP($A2,VLKP!$B$2:$H$40, 3, 0) -> Arts | D2: =VLOOKUP($A2,VLKP!$B$2:$H$40, 4, 0) -> 76 | E2: =VLOOKUP($A2,VLKP!$B$2:$H$40, 5, 0) -> 82 | F2: =VLOOKUP($A2,VLKP!$B$2:$H$40, 6, 0) -> M | G2: =VLOOKUP($A2,VLKP!$B$2:$H$40, 7, 0) -> 22
A3: Mohan | B3: =VLOOKUP($A3,VLKP!$B$2:$H$40, 2, 0) -> Raj | C3: =VLOOKUP($A3,VLKP!$B$2:$H$40, 3, 0) -> Commerce | D3: =VLOOKUP($A3,VLKP!$B$2:$H$40, 4, 0) -> 71 | E3: =VLOOKUP($A3,VLKP!$B$2:$H$40, 5, 0) -> 91 | F3: =VLOOKUP($A3,VLKP!$B$2:$H$40, 6, 0) -> M | G3: =VLOOKUP($A3,VLKP!$B$2:$H$40, 7, 0) -> 34
A4: Deepika | B4: =VLOOKUP($A4,VLKP!$B$2:$H$40, 2, 0) -> Rani | C4: =VLOOKUP($A4,VLKP!$B$2:$H$40, 3, 0) -> Arts | D4: =VLOOKUP($A4,VLKP!$B$2:$H$40, 4, 0) -> 39 | E4: =VLOOKUP($A4,VLKP!$B$2:$H$40, 5, 0) -> 65 | F4: =VLOOKUP($A4,VLKP!$B$2:$H$40, 6, 0) -> F | G4: =VLOOKUP($A4,VLKP!$B$2:$H$40, 7, 0) -> 21
A5: Manohar | B5: =VLOOKUP($A5,VLKP!$B$2:$H$40, 2, 0) -> Babu | C5: =VLOOKUP($A5,VLKP!$B$2:$H$40, 3, 0) -> Commerce | D5: =VLOOKUP($A5,VLKP!$B$2:$H$40, 4, 0) -> 72 | E5: =VLOOKUP($A5,VLKP!$B$2:$H$40, 5, 0) -> 93 | F5: =VLOOKUP($A5,VLKP!$B$2:$H$40, 6, 0) -> M | G5: =VLOOKUP($A5,VLKP!$B$2:$H$40, 7, 0) -> 25
A6: Priyanka | B6: =VLOOKUP($A6,VLKP!$B$2:$H$40, 2, 0) -> Devi | C6: =VLOOKUP($A6,VLKP!$B$2:$H$40, 3, 0) -> Science | D6: =VLOOKUP($A6,VLKP!$B$2:$H$40, 4, 0) -> 60 | E6: =VLOOKUP($A6,VLKP!$B$2:$H$40, 5, 0) -> 73 | F6: =VLOOKUP($A6,VLKP!$B$2:$H$40, 6, 0) -> F | G6: =VLOOKUP($A6,VLKP!$B$2:$H$40, 7, 0) -> 23
A7: Vinoth | B7: =VLOOKUP($A7,VLKP!$B$2:$H$40, 2, 0) -> Muthu | C7: =VLOOKUP($A7,VLKP!$B$2:$H$40, 3, 0) -> Commerce | D7: =VLOOKUP($A7,VLKP!$B$2:$H$40, 4, 0) -> 84 | E7: =VLOOKUP($A7,VLKP!$B$2:$H$40, 5, 0) -> 62 | F7: =VLOOKUP($A7,VLKP!$B$2:$H$40, 6, 0) -> M | G7: =VLOOKUP($A7,VLKP!$B$2:$H$40, 7, 0) -> 26
A8: Shanthi | B8: =VLOOKUP($A8,VLKP!$B$2:$H$40, 2, 0) -> Lakshmi | C8: =VLOOKUP($A8,VLKP!$B$2:$H$40, 3, 0) -> Arts | D8: =VLOOKUP($A8,VLKP!$B$2:$H$40, 4, 0) -> 60 | E8: =VLOOKUP($A8,VLKP!$B$2:$H$40, 5, 0) -> 86 | F8: =VLOOKUP($A8,VLKP!$B$2:$H$40, 6, 0) -> F | G8: =VLOOKUP($A8,VLKP!$B$2:$H$40, 7, 0) -> 29
A9: Manimegalai | B9: =VLOOKUP($A9,VLKP!$B$2:$H$40, 2, 0) -> Selvi | C9: =VLOOKUP($A9,VLKP!$B$2:$H$40, 3, 0) -> Commerce | D9: =VLOOKUP($A9,VLKP!$B$2:$H$40, 4, 0) -> 98 | E9: =VLOOKUP($A9,VLKP!$B$2:$H$40, 5, 0) -> 96 | F9: =VLOOKUP($A9,VLKP!$B$2:$H$40, 6, 0) -> F | G9: =VLOOKUP($A9,VLKP!$B$2:$H$40, 7, 0) -> 28
A10: Karthi | B10: =VLOOKUP($A10,VLKP!$B$2:$H$40, 2, 0) -> Velu | C10: =VLOOKUP($A10,VLKP!$B$2:$H$40, 3, 0) -> Commerce | D10: =VLOOKUP($A10,VLKP!$B$2:$H$40, 4, 0) -> 44 | E10: =VLOOKUP($A10,VLKP!$B$2:$H$40, 5, 0) -> 95 | F10: =VLOOKUP($A10,VLKP!$B$2:$H$40, 6, 0) -> M | G10: =VLOOKUP($A10,VLKP!$B$2:$H$40, 7, 0) -> 22
A11: Mari | B11: =VLOOKUP($A11,VLKP!$B$2:$H$40, 2, 0) -> Gopi | C11: =VLOOKUP($A11,VLKP!$B$2:$H$40, 3, 0) -> Science | D11: =VLOOKUP($A11,VLKP!$B$2:$H$40, 4, 0) -> 94 | E11: =VLOOKUP($A11,VLKP!$B$2:$H$40, 5, 0) -> 66 | F11: =VLOOKUP($A11,VLKP!$B$2:$H$40, 6, 0) -> M | G11: =VLOOKUP($A11,VLKP!$B$2:$H$40, 7, 0) -> 23
A12: Mahesh | B12: =VLOOKUP($A12,VLKP!$B$2:$H$40, 2, 0) -> Sekar | C12: =VLOOKUP($A12,VLKP!$B$2:$H$40, 3, 0) -> Arts | D12: =VLOOKUP($A12,VLKP!$B$2:$H$40, 4, 0) -> 78 | E12: =VLOOKUP($A12,VLKP!$B$2:$H$40, 5, 0) -> 65 | F12: =VLOOKUP($A12,VLKP!$B$2:$H$40, 6, 0) -> M | G12: =VLOOKUP($A12,VLKP!$B$2:$H$40, 7, 0) -> 24
A13: Sangeetha | B13: =VLOOKUP($A13,VLKP!$B$2:$H$40, 2, 0) -> Raji | C13: =VLOOKUP($A13,VLKP!$B$2:$H$40, 3, 0) -> Science | D13: =VLOOKUP($A13,VLKP!$B$2:$H$40, 4, 0) -> 51 | E13: =VLOOKUP($A13,VLKP!$B$2:$H$40, 5, 0) -> 61 | F13: =VLOOKUP($A13,VLKP!$B$2:$H$40, 6, 0) -> F | G13: =VLOOKUP($A13,VLKP!$B$2:$H$40, 7, 0) -> 22
... A40: Nirmal | B40: =VLOOKUP($A40,VLKP!$B$2:$H$40, 2, 0) -> Prakash | C40: =VLOOKUP($A40,VLKP!$B$2:$H$40, 3, 0) -> Commerce | D40: =VLOOKUP($A40,VLKP!$B$2:$H$40, 4, 0) -> 97 | E40: =VLOOKUP($A40,VLKP!$B$2:$H$40, 5, 0) -> 88 | F40: =VLOOKUP($A40,VLKP!$B$2:$H$40, 6, 0) -> M | G40: =VLOOKUP($A40,VLKP!$B$2:$H$40, 7, 0) -> 24

Sheet HLKP
A6: 1 | C6: NAME | D6: Ravi | E6: Mohan | F6: Poorvika | G6: Dinesh | H6: Deepthika
A7: 2 | C7: CLASS | D7: 10th | E7: 10th | F7: 11th | G7: 10th | H7: 11th
A8: 3 | C8: MARK | D8: 67 | E8: 84 | F8: 92 | G8: 78 | H8: 33
D13: =HLOOKUP(D$6, $D$6:$H$8, 2, 0) -> 10th | E13: =HLOOKUP(E6, $D$6:$H$8, 2, 0) -> 10th | F13: =HLOOKUP(F6, $D$6:$H$8, 2, 0) -> 11th | G13: =HLOOKUP(G6, $D$6:$H$8, 2, 0) -> 10th | H13: =HLOOKUP(H6, $D$6:$H$8, 2, 0) -> 11th
D14: =HLOOKUP(D$6, $D$6:$H$8, 3, 0) -> 67 | E14: =HLOOKUP(E$6, $D$6:$H$8, 3, 0) -> 84 | F14: =HLOOKUP(F$6, $D$6:$H$8, 3, 0) -> 92 | G14: =HLOOKUP(G$6, $D$6:$H$8, 3, 0) -> 78 | H14: =HLOOKUP(H$6, $D$6:$H$8, 3, 0) -> 33

Sheet DateTime
A1: TODAY | D1: NOW
A2: Current Date | B2: =TODAY() -> 46133 | D2: Current Time | E2: =NOW() -> 46133.896
A4: DAY | D4: MONTH
A5: 44180 | B5: =DAY(A5) -> 15 | D5: 44180 | E5: =MONTH(D5) -> 12
A6: 34939 | B6: =DAY(A6) -> 28 | D6: 34939 | E6: =MONTH(D6) -> 8
A7: 44494 | B7: =DAY(A7) -> 25 | D7: 44494 | E7: =MONTH(D7) -> 10
A9: YEAR | D9: HOUR
A10: 44180 | B10: =YEAR(A10) -> 2020 | D10: 34939.354 | E10: =HOUR(D10) -> 8
A11: 34939 | B11: =YEAR(A11) -> 1995 | D11: 34940.785 | E11: =HOUR(D11) -> 18
A12: 44494 | B12: =YEAR(A12) -> 2021 | D12: 34941.962 | E12: =HOUR(D12) -> 23
A14: MINUTE | D14: SECOND
A15: 34939.354 | B15: =MINUTE(A15) -> 30 | D15: 44424.984 | E15: =SECOND(D15) -> 14
A16: 34940.785 | B16: =MINUTE(A16) -> 50 | D16: 0.27821759 | E16: =SECOND(D16) -> 38
A17: 34941.962 | B17: =MINUTE(A17) -> 5 | D17: 0.52135417 | E17: =SECOND(D17) -> 45
A19: DATE VALUE | D19: TIME VALUE
A20: 28/08 | B20: =DATEVALUE(A20) -> 46262 | C20: shift + 3 | D20: 8:30 Pm | E20: =TIMEVALUE(D20) -> 0.85416667
A21: 28/ 1995 | B21: =DATEVALUE(A21) -> #VALUE! | D21: 19:30 | E21: =TIMEVALUE(D21) -> 0.8125
A22: 1995-08-28 | B22: =DATEVALUE(A22) -> 34939 | D22: 2:30 am | E22: =TIMEVALUE(D22) -> 0.10416667
A24: EDATE | D24: EOMONTH
A25: 34939 | B25: =EDATE(A25,1) -> 34970 | D25: 34939 | E25: =EOMONTH(D25,2) -> 35003
A26: 43997 | B26: =EDATE(A26,10) -> 44301 | D26: 43997 | E26: =EOMONTH(D26,13) -> 44408
A27: 44190 | B27: =EDATE(A27,-10) -> 43886 | D27: 44190 | E27: =EOMONTH(D27,-2) -> 44135
A29: DATE | D29: TIME
A30: 8 | B30: =DATE(A32,A30,A31) -> 44071 | C30: 08-28-2020 | D30: 8 | E30: =TIME(D30,D31,D32) -> 0.35483796
A31: 28 | D31: 30
A32: 2020 | D32: 58
A34: DAYS
A35: 34939 | B35: 44162
A36: 41268 | B36: 44163
A37: 44129 | B37: 44162
